Workbook

Sheet master-sheet-football
A1: University URL wiki | B1: University | C1: Common Name | D1: Nickname | E1: City | F1: State | G1: Type | H1: Subdivision | I1: Primary | J1: University URL sport-ref | K1: Roster count 2025 | L1: Roster count 2024 | M1: Roster count 2023
A2: https://en.wikipedia.org/wiki/Abilene_Christian_University | B2: Abilene Christian University | C2: Abilene Christian | D2: Wildcats | E2: Abilene | F2: TX | G2: Private | H2: FCS | I2: Western Athletic Conference | J2: {=XLOOKUP(B2, 'name-mapping-football'!C:C, 'name-mapping-football'!A:A, "")}
A3: https://en.wikipedia.org/wiki/Alabama_A%26M_University | B3: Alabama Agricultural and Mechanical University | C3: Alabama A&M | D3: Bulldogs | E3: Normal | F3: AL | G3: Public | H3: FCS | I3: Southwestern Athletic Conference | J3: {=XLOOKUP(B3, 'name-mapping-football'!C:C, 'name-mapping-football'!A:A, "")}
A4: https://en.wikipedia.org/wiki/Alabama_State_University | B4: Alabama State University | C4: Alabama State | D4: Hornets | E4: Montgomery | F4: AL | G4: Public | H4: FCS | I4: Southwestern Athletic Conference | J4: {=XLOOKUP(B4, 'name-mapping-football'!C:C, 'name-mapping-football'!A:A, "")}
A5: https://en.wikipedia.org/wiki/Alcorn_State_University | B5: Alcorn State University | C5: Alcorn State | D5: Braves | E5: Lorman | F5: MS | G5: Public | H5: FCS | I5: Southwestern Athletic Conference | J5: {=XLOOKUP(B5, 'name-mapping-football'!C:C, 'name-mapping-football'!A:A, "")}
A6: https://en.wikipedia.org/wiki/American_University | B6: American University | C6: American | D6: Eagles | E6: Washington | F6: DC | G6: Private | H6: Non-football | I6: Patriot League | J6: {=XLOOKUP(B6, 'name-mapping-football'!C:C, 'name-mapping-football'!A:A, "")} | K6: 0 | L6: 0 | M6: 0
A7: https://en.wikipedia.org/wiki/Appalachian_State_University | B7: Appalachian State University | C7: Appalachian State | D7: Mountaineers | E7: Boone | F7: NC | G7: Public | H7: FBS | I7: Sun Belt Conference | J7: {=XLOOKUP(B7, 'name-mapping-football'!C:C, 'name-mapping-football'!A:A, "")} -> https://www.sports-reference.com/cfb/schools/appalachian-state/
A8: https://en.wikipedia.org/wiki/Arizona_State_University | B8: Arizona State University | C8: Arizona State | D8: Sun Devils | E8: Tempe | F8: AZ | G8: Public | H8: FBS | I8: Big 12 Conference | J8: {=XLOOKUP(B8, 'name-mapping-football'!C:C, 'name-mapping-football'!A:A, "")} -> https://www.sports-reference.com/cfb/schools/arizona-state/
A9: https://en.wikipedia.org/wiki/Arkansas_State_University | B9: Arkansas State University | C9: Arkansas State | D9: Red Wolves | E9: Jonesboro | F9: AR | G9: Public | H9: FBS | I9: Sun Belt Conference | J9: {=XLOOKUP(B9, 'name-mapping-football'!C:C, 'name-mapping-football'!A:A, "")} -> https://www.sports-reference.com/cfb/schools/arkansas-state/
A10: https://en.wikipedia.org/wiki/Auburn_University | B10: Auburn University | C10: Auburn | D10: Tigers | E10: Auburn | F10: AL | G10: Public | H10: FBS | I10: Southeastern Conference | J10: {=XLOOKUP(B10, 'name-mapping-football'!C:C, 'name-mapping-football'!A:A, "")} -> https://www.sports-reference.com/cfb/schools/auburn/
A11: https://en.wikipedia.org/wiki/Austin_Peay_State_University | B11: Austin Peay State University | C11: Austin Peay | D11: Governors | E11: Clarksville | F11: TN | G11: Public | H11: FCS | I11: Atlantic Sun Conference | J11: {=XLOOKUP(B11, 'name-mapping-football'!C:C, 'name-mapping-football'!A:A, "")}
A12: https://en.wikipedia.org/wiki/Ball_State_University | B12: Ball State University | C12: Ball State | D12: Cardinals | E12: Muncie | F12: IN | G12: Public | H12: FBS | I12: Mid-American Conference | J12: {=XLOOKUP(B12, 'name-mapping-football'!C:C, 'name-mapping-football'!A:A, "")} -> https://www.sports-reference.com/cfb/schools/ball-state/
A13: https://en.wikipedia.org/wiki/Baylor_University | B13: Baylor University | C13: Baylor | D13: Bears | E13: Waco | F13: TX | G13: Private | H13: FBS | I13: Big 12 Conference | J13: {=XLOOKUP(B13, 'name-mapping-football'!C:C, 'name-mapping-football'!A:A, "")} -> https://www.sports-reference.com/cfb/schools/baylor/
A14: https://en.wikipedia.org/wiki/Bellarmine_University | B14: Bellarmine University | C14: Bellarmine | D14: Knights | E14: Louisville | F14: KY | G14: Private | H14: Non-football | I14: Atlantic Sun Conference | J14: {=XLOOKUP(B14, 'name-mapping-football'!C:C, 'name-mapping-football'!A:A, "")} | K14: 0 | L14: 0 | M14: 0
A15: https://en.wikipedia.org/wiki/Belmont_University | B15: Belmont University | C15: Belmont | D15: Bruins | E15: Nashville | F15: TN | G15: Private | H15: Non-football | I15: Missouri Valley Conference | J15: {=XLOOKUP(B15, 'name-mapping-football'!C:C, 'name-mapping-football'!A:A, "")} | K15: 0 | L15: 0 | M15: 0
A16: https://en.wikipedia.org/wiki/Bethune%E2%80%93Cookman_University | B16: Bethune–Cookman University | C16: Bethune–Cookman | D16: Wildcats | E16: Daytona Beach | F16: FL | G16: Private | H16: FCS | I16: Southwestern Athletic Conference | J16: {=XLOOKUP(B16, 'name-mapping-football'!C:C, 'name-mapping-football'!A:A, "")}
A17: https://en.wikipedia.org/wiki/Boise_State_University | B17: Boise State University | C17: Boise State | D17: Broncos | E17: Boise | F17: ID | G17: Public | H17: FBS | I17: Mountain West Conference | J17: {=XLOOKUP(B17, 'name-mapping-football'!C:C, 'name-mapping-football'!A:A, "")} -> https://www.sports-reference.com/cfb/schools/boise-state/
A18: https://en.wikipedia.org/wiki/Boston_College | B18: Boston College | C18: Boston College | D18: Eagles | E18: Chestnut Hill | F18: MA | G18: Private | H18: FBS | I18: Atlantic Coast Conference | J18: {=XLOOKUP(B18, 'name-mapping-football'!C:C, 'name-mapping-football'!A:A, "")} -> https://www.sports-reference.com/cfb/schools/boston-college/
A19: https://en.wikipedia.org/wiki/Boston_University | B19: Boston University | C19: Boston University | D19: Terriers | E19: Boston | F19: MA | G19: Private | H19: Non-football | I19: Patriot League | J19: {=XLOOKUP(B19, 'name-mapping-football'!C:C, 'name-mapping-football'!A:A, "")} | K19: 0 | L19: 0 | M19: 0
A20: https://en.wikipedia.org/wiki/Bowling_Green_State_University | B20: Bowling Green State University | C20: Bowling Green | D20: Falcons | E20: Bowling Green | F20: OH | G20: Public | H20: FBS | I20: Mid-American Conference | J20: {=XLOOKUP(B20, 'name-mapping-football'!C:C, 'name-mapping-football'!A:A, "")} -> https://www.sports-reference.com/cfb/schools/bowling-green-state/
A21: https://en.wikipedia.org/wiki/Bradley_University | B21: Bradley University | C21: Bradley | D21: Braves | E21: Peoria | F21: IL | G21: Private | H21: Non-football | I21: Missouri Valley Conference | J21: {=XLOOKUP(B21, 'name-mapping-football'!C:C, 'name-mapping-football'!A:A, "")} | K21: 0 | L21: 0 | M21: 0
A22: https://en.wikipedia.org/wiki/Brigham_Young_University | B22: Brigham Young University | C22: BYU | D22: Cougars | E22: Provo | F22: UT | G22: Private | H22: FBS | I22: Big 12 Conference | J22: {=XLOOKUP(B22, 'name-mapping-football'!C:C, 'name-mapping-football'!A:A, "")} -> https://www.sports-reference.com/cfb/schools/brigham-young/
A23: https://en.wikipedia.org/wiki/Brown_University | B23: Brown University | C23: Brown | D23: Bears | E23: Providence | F23: RI | G23: Private | H23: FCS | I23: Ivy League | J23: {=XLOOKUP(B23, 'name-mapping-football'!C:C, 'name-mapping-football'!A:A, "")}
A24: https://en.wikipedia.org/wiki/Bryant_University | B24: Bryant University | C24: Bryant | D24: Bulldogs | E24: Smithfield | F24: RI | G24: Private | H24: FCS | I24: America East Conference | J24: {=XLOOKUP(B24, 'name-mapping-football'!C:C, 'name-mapping-football'!A:A, "")}
A25: https://en.wikipedia.org/wiki/Bucknell_University | B25: Bucknell University | C25: Bucknell | D25: Bison | E25: Lewisburg | F25: PA | G25: Private | H25: FCS | I25: Patriot League | J25: {=XLOOKUP(B25, 'name-mapping-football'!C:C, 'name-mapping-football'!A:A, "")}
A26: https://en.wikipedia.org/wiki/Butler_University | B26: Butler University | C26: Butler | D26: Bulldogs | E26: Indianapolis | F26: IN | G26: Private | H26: FCS | I26: Big East Conference | J26: {=XLOOKUP(B26, 'name-mapping-football'!C:C, 'name-mapping-football'!A:A, "")}
A27: https://en.wikipedia.org/wiki/California_Baptist_University | B27: California Baptist University | C27: Cal Baptist | D27: Lancers | E27: Riverside | F27: CA | G27: Private | H27: Non-football | I27: Western Athletic Conference | J27: {=XLOOKUP(B27, 'name-mapping-football'!C:C, 'name-mapping-football'!A:A, "")} | K27: 0 | L27: 0 | M27: 0
A28: https://en.wikipedia.org/wiki/California_Polytechnic_State_University,_San_Luis_Obispo | B28: California Polytechnic State University | C28: Cal Poly | D28: Mustangs | E28: San Luis Obispo | F28: CA | G28: Public | H28: FCS | I28: Big West Conference | J28: {=XLOOKUP(B28, 'name-mapping-football'!C:C, 'name-mapping-football'!A:A, "")}
A29: https://en.wikipedia.org/wiki/California_State_University,_Bakersfield | B29: California State University, Bakersfield | C29: Bakersfield | D29: Roadrunners | E29: Bakersfield | F29: CA | G29: Public | H29: Non-football | I29: Big West Conference | J29: {=XLOOKUP(B29, 'name-mapping-football'!C:C, 'name-mapping-football'!A:A, "")} | K29: 0 | L29: 0 | M29: 0
A30: https://en.wikipedia.org/wiki/California_State_University,_Fresno | B30: California State University, Fresno | C30: Fresno State | D30: Bulldogs | E30: Fresno | F30: CA | G30: Public | H30: FBS | I30: Mountain West Conference | J30: {=XLOOKUP(B30, 'name-mapping-football'!C:C, 'name-mapping-football'!A:A, "")} -> https://www.sports-reference.com/cfb/schools/fresno-state/
A31: https://en.wikipedia.org/wiki/California_State_University,_Fullerton | B31: California State University, Fullerton | C31: Cal State Fullerton | D31: Titans | E31: Fullerton | F31: CA | G31: Public | H31: Non-football | I31: Big West Conference | J31: {=XLOOKUP(B31, 'name-mapping-football'!C:C, 'name-mapping-football'!A:A, "")} | K31: 0 | L31: 0 | M31: 0
A32: https://en.wikipedia.org/wiki/California_State_University,_Long_Beach | B32: California State University, Long Beach | C32: Long Beach State | D32: Beach | E32: Long Beach | F32: CA | G32: Public | H32: Non-football | I32: Big West Conference | J32: {=XLOOKUP(B32, 'name-mapping-football'!C:C, 'name-mapping-football'!A:A, "")} | K32: 0 | L32: 0 | M32: 0
A33: https://en.wikipedia.org/wiki/California_State_University,_Northridge | B33: California State University, Northridge | C33: Cal State Northridge / CSUN | D33: Matadors | E33: Northridge | F33: CA | G33: Public | H33: Non-football | I33: Big West Conference | J33: {=XLOOKUP(B33, 'name-mapping-football'!C:C, 'name-mapping-football'!A:A, "")} | K33: 0 | L33: 0 | M33: 0
A34: https://en.wikipedia.org/wiki/California_State_University,_Sacramento | B34: California State University, Sacramento | C34: Sacramento State | D34: Hornets | E34: Sacramento | F34: CA | G34: Public | H34: FCS | I34: Big Sky Conference | J34: {=XLOOKUP(B34, 'name-mapping-football'!C:C, 'name-mapping-football'!A:A, "")}
A35: https://en.wikipedia.org/wiki/Campbell_University | B35: Campbell University | C35: Campbell | D35: Fighting Camels | E35: Buies Creek | F35: NC | G35: Private | H35: FCS | I35: Coastal Athletic Association | J35: {=XLOOKUP(B35, 'name-mapping-football'!C:C, 'name-mapping-football'!A:A, "")}
A36: https://en.wikipedia.org/wiki/Canisius_University | B36: Canisius University | C36: Canisius | D36: Golden Griffins | E36: Buffalo | F36: NY | G36: Private | H36: Non-football | I36: Metro Atlantic Athletic Conference | J36: {=XLOOKUP(B36, 'name-mapping-football'!C:C, 'name-mapping-football'!A:A, "")} | K36: 0 | L36: 0 | M36: 0
A37: https://en.wikipedia.org/wiki/Central_Connecticut_State_University | B37: Central Connecticut State University | C37: Central Connecticut | D37: Blue Devils | E37: New Britain | F37: CT | G37: Public | H37: FCS | I37: NEC | J37: {=XLOOKUP(B37, 'name-mapping-football'!C:C, 'name-mapping-football'!A:A, "")}
A38: https://en.wikipedia.org/wiki/Central_Michigan_University | B38: Central Michigan University | C38: Central Michigan | D38: Chippewas | E38: Mount Pleasant | F38: MI | G38: Public | H38: FBS | I38: Mid-American Conference | J38: {=XLOOKUP(B38, 'name-mapping-football'!C:C, 'name-mapping-football'!A:A, "")} -> https://www.sports-reference.com/cfb/schools/central-michigan/
A39: https://en.wikipedia.org/wiki/Charleston_Southern_University | B39: Charleston Southern University | C39: Charleston Southern | D39: Buccaneers | E39: North Charleston | F39: SC | G39: Private | H39: FCS | I39: Big South Conference | J39: {=XLOOKUP(B39, 'name-mapping-football'!C:C, 'name-mapping-football'!A:A, "")}
A40: https://en.wikipedia.org/wiki/Chicago_State_University | B40: Chicago State University | C40: Chicago State | D40: Cougars | E40: Chicago | F40: IL | G40: Public | H40: Non-football | I40: NEC | J40: {=XLOOKUP(B40, 'name-mapping-football'!C:C, 'name-mapping-football'!A:A, "")} | K40: 0 | L40: 0 | M40: 0
...

Sheet name-mapping-football
A1: School url | B1: Website Name | C1: University | D1: Nickname
A2: https://www.sports-reference.com/cfb/schools/air-force/ | B2: Air Force | C2: United States Air Force Academy | D2: Falcons
A3: https://www.sports-reference.com/cfb/schools/akron/ | B3: Akron | C3: The University of Akron | D3: Zips
A4: https://www.sports-reference.com/cfb/schools/alabama/ | B4: Alabama | C4: The University of Alabama | D4: Crimson Tide
A5: https://www.sports-reference.com/cfb/schools/appalachian-state/ | B5: Appalachian State | C5: Appalachian State University | D5: Mountaineers
A6: https://www.sports-reference.com/cfb/schools/arizona/ | B6: Arizona | C6: University of Arizona | D6: Wildcats
A7: https://www.sports-reference.com/cfb/schools/arizona-state/ | B7: Arizona State | C7: Arizona State University | D7: Sun Devils
A8: https://www.sports-reference.com/cfb/schools/arkansas/ | B8: Arkansas | C8: University of Arkansas | D8: Razorbacks
A9: https://www.sports-reference.com/cfb/schools/arkansas-state/ | B9: Arkansas State | C9: Arkansas State University | D9: Red Wolves
A10: https://www.sports-reference.com/cfb/schools/army/ | B10: Army | C10: United States Military Academy | D10: Black Knights
A11: https://www.sports-reference.com/cfb/schools/auburn/ | B11: Auburn | C11: Auburn University | D11: Tigers
A12: https://www.sports-reference.com/cfb/schools/ball-state/ | B12: Ball State | C12: Ball State University | D12: Cardinals
... A137: https://www.sports-reference.com/cfb/schools/wyoming/ | B137: Wyoming | C137: University of Wyoming | D137: Cowboys

Sheet school_urls-football
A1: School url | B1: Common Name | C1: From | D1: To | E1: Yrs | F1: Overall G | G1: Overall W | H1: Overall L | I1: Overall T | J1: Overall Pct | K1: Bowls G | L1: Bowls W | M1: Bowls L | N1: Bowls T | O1: Bowls PCT | P1: SRS SRS | Q1: SRS SOS | R1: AP | S1: CC
A2: https://www.sports-reference.com/cfb/schools/air-force/ | B2: Air Force | C2: 1957 | D2: 2025 | E2: 69 | F2: 803 | G2: 436 | H2: 355 | I2: 12 | J2: 0.55 | K2: 30 | L2: 16 | M2: 13 | N2: 1 | O2: 0.55 | P2: 1.09 | Q2: -0.94 | R2: 7 | S2: 3
A3: https://www.sports-reference.com/cfb/schools/akron/ | B3: Akron | C3: 1975 | D3: 2025 | E3: 40 | F3: 461 | G3: 166 | H3: 292 | I3: 3 | J3: 0.363 | K3: 3 | L3: 1 | M3: 2 | N3: 0.333 | O3: -12.06 | P3: -6.58 | Q3: 1 | R3: 0 | S3: 0
A4: https://www.sports-reference.com/cfb/schools/alabama/ | B4: Alabama | C4: 1902 | D4: 2025 | E4: 122 | F4: 1360 | G4: 999 | H4: 319 | I4: 42 | J4: 0.75 | K4: 80 | L4: 47 | M4: 30 | N4: 3 | O4: 0.606 | P4: 13.86 | Q4: 4.33 | R4: 63 | S4: 30
A5: https://www.sports-reference.com/cfb/schools/alameda-coast-guard/ | B5: Alameda Coast Guard | C5: 1943 | D5: 1944 | E5: 2 | F5: 15 | G5: 8 | H5: 4 | I5: 3 | J5: 0.633 | K5: -0.16 | L5: -5.13 | M5: 0 | N5: 0 | O5: 0 | P5: 0 | R5: 0 | S5: 0
A6: https://www.sports-reference.com/cfb/schools/alcorn-state/ | B6: Alcorn State | C6: 1977 | D6: 1977 | E6: 1 | F6: 11 | G6: 3 | H6: 8 | I6: 0.273 | J6: -17.1 | K6: -9.19 | L6: 0 | M6: 0 | N6: 0 | O6: 0 | P6: 0 | R6: 0 | S6: 0
A7: https://www.sports-reference.com/cfb/schools/amarillo-field/ | B7: Amarillo Field | C7: 1944 | D7: 1944 | E7: 1 | F7: 8 | G7: 5 | H7: 3 | I7: 0.625 | J7: 5.1 | K7: -1.78 | L7: 0 | M7: 0 | N7: 0 | O7: 0 | P7: 0 | R7: 0 | S7: 0
A8: https://www.sports-reference.com/cfb/schools/amherst/ | B8: Amherst | C8: 1877 | D8: 1906 | E8: 25 | F8: 239 | G8: 108 | H8: 109 | I8: 22 | J8: 0.498 | K8: -1.08 | L8: 0 | M8: 0 | N8: 0 | O8: 0 | P8: -0.09 | R8: 0 | S8: 0
A9: https://www.sports-reference.com/cfb/schools/appalachian-state/ | B9: Appalachian State | C9: 1972 | D9: 2025 | E9: 22 | F9: 264 | G9: 154 | H9: 105 | I9: 5 | J9: 0.593 | K9: 9 | L9: 7 | M9: 2 | N9: 0 | O9: 0.778 | P9: -1.45 | Q9: -5.93 | R9: 1 | S9: 4
A10: https://www.sports-reference.com/cfb/schools/arizona/ | B10: Arizona | C10: 1931 | D10: 2025 | E10: 92 | F10: 1010 | G10: 519 | H10: 468 | I10: 23 | J10: 0.525 | K10: 22 | L10: 10 | M10: 11 | N10: 1 | O10: 0.477 | P10: 1.45 | Q10: 0.71 | R10: 8 | S10: 6
A11: https://www.sports-reference.com/cfb/schools/arizona-state/ | B11: Arizona State | C11: 1931 | D11: 2025 | E11: 92 | F11: 1018 | G11: 611 | H11: 389 | I11: 18 | J11: 0.609 | K11: 35 | L11: 15 | M11: 19 | N11: 1 | O11: 0.443 | P11: 3.53 | Q11: -1.08 | R11: 18 | S11: 18
A12: https://www.sports-reference.com/cfb/schools/arkansas/ | B12: Arkansas | C12: 1906 | D12: 2025 | E12: 120 | F12: 1284 | G12: 715 | H12: 532 | I12: 37 | J12: 0.571 | K12: 45 | L12: 18 | M12: 24 | N12: 3 | O12: 0.433 | P12: 6.39 | Q12: 3.13 | R12: 29 | S12: 14
A13: https://www.sports-reference.com/cfb/schools/arkansas-state/ | B13: Arkansas State | C13: 1974 | D13: 2025 | E13: 44 | F13: 518 | G13: 231 | H13: 285 | I13: 2 | J13: 0.448 | K13: 13 | L13: 6 | M13: 7 | N13: 0 | O13: 0.462 | P13: -8.88 | Q13: -6.48 | R13: 0 | S13: 7
A14: https://www.sports-reference.com/cfb/schools/army/ | B14: Army | C14: 1891 | D14: 2025 | E14: 132 | F14: 1329 | G14: 732 | H14: 546 | I14: 51 | J14: 0.57 | K14: 12 | L14: 9 | M14: 3 | N14: 0 | O14: 0.75 | P14: 3.29 | Q14: -0.36 | R14: 16 | S14: 1
A15: https://www.sports-reference.com/cfb/schools/auburn/ | B15: Auburn | C15: 1902 | D15: 2025 | E15: 123 | F15: 1301 | G15: 783 | H15: 475 | I15: 43 | J15: 0.618 | K15: 47 | L15: 24 | M15: 21 | N15: 2 | O15: 0.532 | P15: 8.79 | Q15: 4.57 | R15: 40 | S15: 8
A16: https://www.sports-reference.com/cfb/schools/ball-state/ | B16: Ball State | C16: 1975 | D16: 2025 | E16: 51 | F16: 588 | G16: 280 | H16: 304 | I16: 4 | J16: 0.48 | K16: 9 | L16: 1 | M16: 8 | N16: 0 | O16: 0.111 | P16: -8.13 | Q16: -6.97 | R16: 1 | S16: 6
A17: https://www.sports-reference.com/cfb/schools/bates/ | B17: Bates | C17: 1901 | D17: 1905 | E17: 3 | F17: 21 | G17: 10 | H17: 8 | I17: 3 | J17: 0.548 | K17: -0.94 | L17: 0 | M17: 0 | N17: 0 | O17: 0 | P17: -1.28 | R17: 0 | S17: 0
A18: https://www.sports-reference.com/cfb/schools/baylor/ | B18: Baylor | C18: 1903 | D18: 2025 | E18: 120 | F18: 1277 | G18: 631 | H18: 605 | I18: 41 | J18: 0.51 | K18: 28 | L18: 14 | M18: 14 | N18: 0 | O18: 0.5 | P18: 2.82 | Q18: 2.71 | R18: 16 | S18: 9
A19: https://www.sports-reference.com/cfb/schools/beloit/ | B19: Beloit | C19: 1894 | D19: 1905 | E19: 9 | F19: 85 | G19: 39 | H19: 36 | I19: 10 | J19: 0.518 | K19: -1.3 | L19: 0 | M19: 0 | N19: 0 | O19: 0 | P19: -1.39 | R19: 0 | S19: 0
A20: https://www.sports-reference.com/cfb/schools/birmingham-southern/ | B20: Birmingham-Southern | C20: 1920 | D20: 1924 | E20: 4 | F20: 36 | G20: 16 | H20: 17 | I20: 3 | J20: 0.486 | K20: -5.29 | L20: 0 | M20: 0 | N20: 0 | O20: 0 | P20: -4.68 | R20: 0 | S20: 0
A21: https://www.sports-reference.com/cfb/schools/boise-state/ | B21: Boise State | C21: 1996 | D21: 2025 | E21: 30 | F21: 384 | G21: 292 | H21: 92 | I21: 0.76 | J21: 23 | K21: 13 | L21: 0 | M21: 10 | N21: 0 | O21: 0.565 | P21: 6.04 | Q21: -3.86 | R21: 14 | S21: 17
A22: https://www.sports-reference.com/cfb/schools/boston-college/ | B22: Boston College | C22: 1901 | D22: 2025 | E22: 91 | F22: 990 | G22: 537 | H22: 439 | I22: 14 | J22: 0.549 | K22: 29 | L22: 15 | M22: 14 | N22: 0 | O22: 0.517 | P22: 1.74 | Q22: 0.07 | R22: 14 | S22: 1
A23: https://www.sports-reference.com/cfb/schools/boston-university/ | B23: Boston University | C23: 1923 | D23: 1964 | E23: 20 | F23: 170 | G23: 73 | H23: 90 | I23: 7 | J23: 0.45 | K23: -6.91 | L23: 0 | M23: 0 | N23: 0 | O23: 0 | P23: -4.99 | Q23: 1 | R23: 0
A24: https://www.sports-reference.com/cfb/schools/bowdoin/ | B24: Bowdoin | C24: 1896 | D24: 1905 | E24: 7 | F24: 66 | G24: 33 | H24: 30 | I24: 3 | J24: 0.523 | K24: -2.71 | L24: 0 | M24: 0 | N24: 0 | O24: 0 | P24: -2.47 | R24: 0 | S24: 0
A25: https://www.sports-reference.com/cfb/schools/bowling-green-state/ | B25: Bowling Green | C25: 1962 | D25: 2025 | E25: 64 | F25: 722 | G25: 383 | H25: 328 | I25: 11 | J25: 0.538 | K25: 15 | L25: 5 | M25: 10 | N25: 0 | O25: 0.333 | P25: -5.41 | Q25: -6.39 | R25: 1 | S25: 9
A26: https://www.sports-reference.com/cfb/schools/bradley/ | B26: Bradley | C26: 1949 | D26: 1951 | E26: 3 | F26: 29 | G26: 14 | H26: 15 | I26: 0.483 | J26: -12.91 | K26: -12.75 | L26: 0 | M26: 0 | N26: 0 | O26: 0 | P26: 0 | R26: 0 | S26: 0
A27: https://www.sports-reference.com/cfb/schools/brown/ | B27: Brown | C27: 1878 | D27: 1981 | E27: 93 | F27: 858 | G27: 431 | H27: 392 | I27: 35 | J27: 0.523 | K27: 1 | L27: 0 | M27: 1 | N27: 0 | O27: 0 | P27: -2.89 | Q27: -3.54 | R27: 0 | S27: 1
A28: https://www.sports-reference.com/cfb/schools/bucknell/ | B28: Bucknell | C28: 1888 | D28: 1946 | E28: 40 | F28: 357 | G28: 168 | H28: 157 | I28: 32 | J28: 0.515 | K28: 1 | L28: 1 | M28: 0 | N28: 0 | O28: 1 | P28: -2.93 | Q28: -2.85 | R28: 0 | S28: 0
A29: https://www.sports-reference.com/cfb/schools/buffalo/ | B29: Buffalo | C29: 1962 | D29: 2025 | E29: 36 | F29: 409 | G29: 163 | H29: 241 | I29: 4 | J29: 0.404 | K29: 7 | L29: 4 | M29: 3 | N29: 0 | O29: 0.571 | P29: -9.8 | Q29: -7.11 | R29: 1 | S29: 1
A30: https://www.sports-reference.com/cfb/schools/butler/ | B30: Butler | C30: 1932 | D30: 1933 | E30: 2 | F30: 15 | G30: 4 | H30: 10 | I30: 1 | J30: 0.3 | K30: -16.48 | L30: 0 | M30: 0 | N30: 0 | O30: 0 | P30: -10.26 | R30: 0 | S30: 0
A31: https://www.sports-reference.com/cfb/schools/brigham-young/ | B31: BYU | C31: 1922 | D31: 2025 | E31: 101 | F31: 1112 | G31: 639 | H31: 447 | I31: 26 | J31: 0.586 | K31: 42 | L31: 19 | M31: 22 | N31: 1 | O31: 0.464 | P31: -0.43 | Q31: -2.91 | R31: 21 | S31: 23
A32: https://www.sports-reference.com/cfb/schools/cal-state-fullerton/ | B32: Cal State Fullerton | C32: 1975 | D32: 1992 | E32: 18 | F32: 205 | G32: 76 | H32: 127 | I32: 2 | J32: 0.376 | K32: 1 | L32: 0 | M32: 1 | N32: 0 | O32: 0 | P32: -12.72 | Q32: -7.22 | R32: 0 | S32: 2
A33: https://www.sports-reference.com/cfb/schools/cal-state-los-angeles/ | B33: Cal State Los Angeles | C33: 1969 | D33: 1971 | E33: 3 | F33: 29 | G33: 3 | H33: 26 | I33: 0.103 | J33: -27.59 | K33: -9.75 | L33: 0 | M33: 0 | N33: 0 | O33: 0 | P33: 0 | R33: 0 | S33: 0
A34: https://www.sports-reference.com/cfb/schools/california/ | B34: California | C34: 1916 | D34: 2025 | E34: 110 | F34: 1195 | G34: 608 | H34: 556 | I34: 31 | J34: 0.522 | K34: 27 | L34: 12 | M34: 14 | N34: 1 | O34: 0.463 | P34: 5.11 | Q34: 3.94 | R34: 14 | S34: 13
A35: https://www.sports-reference.com/cfb/schools/california-santa-barbara/ | B35: California-Santa Barbara | C35: 1969 | D35: 1971 | E35: 3 | F35: 32 | G35: 11 | H35: 21 | I35: 0.344 | J35: -13.35 | K35: -7.22 | L35: 0 | M35: 0 | N35: 0 | O35: 0 | P35: 0 | R35: 0 | S35: 0
A36: https://www.sports-reference.com/cfb/schools/camp-grant/ | B36: Camp Grant | C36: 1943 | D36: 1943 | E36: 1 | F36: 10 | G36: 2 | H36: 6 | I36: 2 | J36: 0.3 | K36: 8.98 | L36: 0 | M36: 0 | N36: 0 | O36: 0 | P36: 14.38 | R36: 0 | S36: 0
A37: https://www.sports-reference.com/cfb/schools/carlisle/ | B37: Carlisle | C37: 1896 | D37: 1917 | E37: 21 | F37: 252 | G37: 165 | H37: 77 | I37: 10 | J37: 0.675 | K37: 8.26 | L37: 0 | M37: 0 | N37: 0 | O37: 0 | P37: 0.94 | R37: 0 | S37: 0
A38: https://www.sports-reference.com/cfb/schools/carnegie-mellon/ | B38: Carnegie Mellon | C38: 1910 | D38: 1940 | E38: 20 | F38: 172 | G38: 84 | H38: 75 | I38: 13 | J38: 0.526 | K38: 1 | L38: 0 | M38: 1 | N38: 0 | O38: 0 | P38: 4.03 | Q38: 1.5 | R38: 1 | S38: 0
A39: https://www.sports-reference.com/cfb/schools/centenary-la/ | B39: Centenary (LA) | C39: 1930 | D39: 1941 | E39: 12 | F39: 131 | G39: 69 | H39: 48 | I39: 14 | J39: 0.58 | K39: 1 | L39: 0 | M39: 0 | N39: 1 | O39: 0.5 | P39: 0.22 | Q39: -1.79 | R39: 0 | S39: 0
A40: https://www.sports-reference.com/cfb/schools/central-michigan/ | B40: Central Michigan | C40: 1975 | D40: 2025 | E40: 51 | F40: 593 | G40: 313 | H40: 269 | I40: 11 | J40: 0.537 | K40: 14 | L40: 4 | M40: 10 | N40: 0 | O40: 0.286 | P40: -6.67 | Q40: -7.62 | R40: 1 | S40: 7
...

Sheet Sheet-1-all-teams
A1: University URL wiki | B1: Source URL | C1: University | D1: School name | E1: Nickname | F1: City | G1: State | H1: Type | I1: Division | J1: Conference | K1: Roster count 2026 | L1: Roster count 2025 | M1: Roster count 2024 | N1: Avg Roster Count Last 3 years | O1: Sport | P1: Num of seasons | Q1: Estimated Athlete pool | R1: Pro Players Count | S1: Draft Probability | T1: National Average | U1: Vs_National_Average
A2: https://en.wikipedia.org/wiki/Abilene_Christian_University | C2: Abilene Christian University | D2: Abilene Christian | E2: Wildcats | F2: Abilene | G2: TX | H2: Private | I2: FCS | J2: Western Athletic Conference | N2: 0 | O2: American Football | P2: 10 | Q2: =P2*N2 -> 0 | R2: {=IF(O2="American Football", XLOOKUP(C2, drafts_football!A:A, drafts_football!B:B, 0), "")} -> 0 | S2: =IF(Q2 = 0, 0, R2/Q2) -> 0 | T2: 0.013414865 | U2: =S2-T2 -> -0.013414865
A3: https://en.wikipedia.org/wiki/Alabama_A%26M_University | C3: Alabama Agricultural and Mechanical University | D3: Alabama A&M | E3: Bulldogs | F3: Normal | G3: AL | H3: Public | I3: FCS | J3: Southwestern Athletic Conference | N3: 0 | O3: American Football | P3: 10 | Q3: =P3*N3 -> 0 | R3: {=IF(O3="American Football", XLOOKUP(C3, drafts_football!A:A, drafts_football!B:B, 0), "")} -> 1 | S3: =IF(Q3 = 0, 0, R3/Q3) -> 0 | T3: 0.013414865 | U3: =S3-T3 -> -0.013414865
A4: https://en.wikipedia.org/wiki/Alabama_State_University | C4: Alabama State University | D4: Alabama State | E4: Hornets | F4: Montgomery | G4: AL | H4: Public | I4: FCS | J4: Southwestern Athletic Conference | N4: 0 | O4: American Football | P4: 10 | Q4: =P4*N4 -> 0 | R4: {=IF(O4="American Football", XLOOKUP(C4, drafts_football!A:A, drafts_football!B:B, 0), "")} -> 2 | S4: =IF(Q4 = 0, 0, R4/Q4) -> 0 | T4: 0.013414865 | U4: =S4-T4 -> -0.013414865
A5: https://en.wikipedia.org/wiki/Alcorn_State_University | C5: Alcorn State University | D5: Alcorn State | E5: Braves | F5: Lorman | G5: MS | H5: Public | I5: FCS | J5: Southwestern Athletic Conference | N5: 0 | O5: American Football | P5: 10 | Q5: =P5*N5 -> 0 | R5: {=IF(O5="American Football", XLOOKUP(C5, drafts_football!A:A, drafts_football!B:B, 0), "")} -> 0 | S5: =IF(Q5 = 0, 0, R5/Q5) -> 0 | T5: 0.013414865 | U5: =S5-T5 -> -0.013414865
A6: https://en.wikipedia.org/wiki/American_University | C6: American University | D6: American | E6: Eagles | F6: Washington | G6: DC | H6: Private | I6: Non-football | J6: Patriot League | K6: 0 | L6: 0 | M6: 0 | N6: 0 | O6: American Football | P6: 10 | Q6: =P6*N6 -> 0 | R6: {=IF(O6="American Football", XLOOKUP(C6, drafts_football!A:A, drafts_football!B:B, 0), "")} -> 0 | S6: =IF(Q6 = 0, 0, R6/Q6) -> 0 | T6: 0.013414865 | U6: =S6-T6 -> -0.013414865
A7: https://en.wikipedia.org/wiki/Appalachian_State_University | B7: https://www.sports-reference.com/cfb/schools/appalachian-state/ | C7: Appalachian State University | D7: Appalachian State | E7: Mountaineers | F7: Boone | G7: NC | H7: Public | I7: FBS | J7: Sun Belt Conference | L7: 120 | M7: 114 | N7: 117 | O7: American Football | P7: 10 | Q7: =P7*N7 -> 1170 | R7: {=IF(O7="American Football", XLOOKUP(C7, drafts_football!A:A, drafts_football!B:B, 0), "")} -> 8 | S7: =IF(Q7 = 0, 0, R7/Q7) -> 0.0068376068 | T7: 0.013414865 | U7: =S7-T7 -> -0.0065772577
A8: https://en.wikipedia.org/wiki/Arizona_State_University | B8: https://www.sports-reference.com/cfb/schools/arizona-state/ | C8: Arizona State University | D8: Arizona State | E8: Sun Devils | F8: Tempe | G8: AZ | H8: Public | I8: FBS | J8: Big 12 Conference | K8: 107 | L8: 119 | M8: 116 | N8: 114 | O8: American Football | P8: 10 | Q8: =P8*N8 -> 1140 | R8: {=IF(O8="American Football", XLOOKUP(C8, drafts_football!A:A, drafts_football!B:B, 0), "")} -> 17 | S8: =IF(Q8 = 0, 0, R8/Q8) -> 0.014912281 | T8: 0.013414865 | U8: =S8-T8 -> 0.0014974161
A9: https://en.wikipedia.org/wiki/Arkansas_State_University | B9: https://www.sports-reference.com/cfb/schools/arkansas-state/ | C9: Arkansas State University | D9: Arkansas State | E9: Red Wolves | F9: Jonesboro | G9: AR | H9: Public | I9: FBS | J9: Sun Belt Conference | K9: 122 | L9: 130 | M9: 121 | N9: 124.3 | O9: American Football | P9: 10 | Q9: =P9*N9 -> 1243 | R9: {=IF(O9="American Football", XLOOKUP(C9, drafts_football!A:A, drafts_football!B:B, 0), "")} -> 0 | S9: =IF(Q9 = 0, 0, R9/Q9) -> 0 | T9: 0.013414865 | U9: =S9-T9 -> -0.013414865
A10: https://en.wikipedia.org/wiki/Auburn_University | B10: https://www.sports-reference.com/cfb/schools/auburn/ | C10: Auburn University | D10: Auburn | E10: Tigers | F10: Auburn | G10: AL | H10: Public | I10: FBS | J10: Southeastern Conference | K10: 114 | L10: 121 | M10: 119 | N10: 118 | O10: American Football | P10: 10 | Q10: =P10*N10 -> 1180 | R10: {=IF(O10="American Football", XLOOKUP(C10, drafts_football!A:A, drafts_football!B:B, 0), "")} -> 41 | S10: =IF(Q10 = 0, 0, R10/Q10) -> 0.034745763 | T10: 0.013414865 | U10: =S10-T10 -> 0.021330898
A11: https://en.wikipedia.org/wiki/Austin_Peay_State_University | C11: Austin Peay State University | D11: Austin Peay | E11: Governors | F11: Clarksville | G11: TN | H11: Public | I11: FCS | J11: Atlantic Sun Conference | N11: 0 | O11: American Football | P11: 10 | Q11: =P11*N11 -> 0 | R11: {=IF(O11="American Football", XLOOKUP(C11, drafts_football!A:A, drafts_football!B:B, 0), "")} -> 0 | S11: =IF(Q11 = 0, 0, R11/Q11) -> 0 | T11: 0.013414865 | U11: =S11-T11 -> -0.013414865
A12: https://en.wikipedia.org/wiki/Ball_State_University | B12: https://www.sports-reference.com/cfb/schools/ball-state/ | C12: Ball State University | D12: Ball State | E12: Cardinals | F12: Muncie | G12: IN | H12: Public | I12: FBS | J12: Mid-American Conference | K12: 106 | L12: 119 | M12: 118 | N12: 114.3 | O12: American Football | P12: 10 | Q12: =P12*N12 -> 1143 | R12: {=IF(O12="American Football", XLOOKUP(C12, drafts_football!A:A, drafts_football!B:B, 0), "")} -> 2 | S12: =IF(Q12 = 0, 0, R12/Q12) -> 0.0017497813 | T12: 0.013414865 | U12: =S12-T12 -> -0.011665083
A13: https://en.wikipedia.org/wiki/Baylor_University | B13: https://www.sports-reference.com/cfb/schools/baylor/ | C13: Baylor University | D13: Baylor | E13: Bears | F13: Waco | G13: TX | H13: Private | I13: FBS | J13: Big 12 Conference | K13: 115 | L13: 113 | M13: 109 | N13: 112.3 | O13: American Football | P13: 10 | Q13: =P13*N13 -> 1123 | R13: {=IF(O13="American Football", XLOOKUP(C13, drafts_football!A:A, drafts_football!B:B, 0), "")} -> 19 | S13: =IF(Q13 = 0, 0, R13/Q13) -> 0.016918967 | T13: 0.013414865 | U13: =S13-T13 -> 0.0035041025
A14: https://en.wikipedia.org/wiki/Bellarmine_University | C14: Bellarmine University | D14: Bellarmine | E14: Knights | F14: Louisville | G14: KY | H14: Private | I14: Non-football | J14: Atlantic Sun Conference | K14: 0 | L14: 0 | M14: 0 | N14: 0 | O14: American Football | P14: 10 | Q14: =P14*N14 -> 0 | R14: {=IF(O14="American Football", XLOOKUP(C14, drafts_football!A:A, drafts_football!B:B, 0), "")} -> 0 | S14: =IF(Q14 = 0, 0, R14/Q14) -> 0 | T14: 0.013414865 | U14: =S14-T14 -> -0.013414865
A15: https://en.wikipedia.org/wiki/Belmont_University | C15: Belmont University | D15: Belmont | E15: Bruins | F15: Nashville | G15: TN | H15: Private | I15: Non-football | J15: Missouri Valley Conference | K15: 0 | L15: 0 | M15: 0 | N15: 0 | O15: American Football | P15: 10 | Q15: =P15*N15 -> 0 | R15: {=IF(O15="American Football", XLOOKUP(C15, drafts_football!A:A, drafts_football!B:B, 0), "")} -> 0 | S15: =IF(Q15 = 0, 0, R15/Q15) -> 0 | T15: 0.013414865 | U15: =S15-T15 -> -0.013414865
A16: https://en.wikipedia.org/wiki/Bethune%E2%80%93Cookman_University | C16: Bethune–Cookman University | D16: Bethune–Cookman | E16: Wildcats | F16: Daytona Beach | G16: FL | H16: Private | I16: FCS | J16: Southwestern Athletic Conference | N16: 0 | O16: American Football | P16: 10 | Q16: =P16*N16 -> 0 | R16: {=IF(O16="American Football", XLOOKUP(C16, drafts_football!A:A, drafts_football!B:B, 0), "")} -> 0 | S16: =IF(Q16 = 0, 0, R16/Q16) -> 0 | T16: 0.013414865 | U16: =S16-T16 -> -0.013414865
A17: https://en.wikipedia.org/wiki/Boise_State_University | B17: https://www.sports-reference.com/cfb/schools/boise-state/ | C17: Boise State University | D17: Boise State | E17: Broncos | F17: Boise | G17: ID | H17: Public | I17: FBS | J17: Mountain West Conference | K17: 108 | L17: 115 | M17: 113 | N17: 112 | O17: American Football | P17: 10 | Q17: =P17*N17 -> 1120 | R17: {=IF(O17="American Football", XLOOKUP(C17, drafts_football!A:A, drafts_football!B:B, 0), "")} -> 17 | S17: =IF(Q17 = 0, 0, R17/Q17) -> 0.015178571 | T17: 0.013414865 | U17: =S17-T17 -> 0.0017637069
A18: https://en.wikipedia.org/wiki/Boston_College | B18: https://www.sports-reference.com/cfb/schools/boston-college/ | C18: Boston College | D18: Boston College | E18: Eagles | F18: Chestnut Hill | G18: MA | H18: Private | I18: FBS | J18: Atlantic Coast Conference | K18: 127 | L18: 117 | M18: 117 | N18: 120.3 | O18: American Football | P18: 10 | Q18: =P18*N18 -> 1203 | R18: {=IF(O18="American Football", XLOOKUP(C18, drafts_football!A:A, drafts_football!B:B, 0), "")} -> 21 | S18: =IF(Q18 = 0, 0, R18/Q18) -> 0.017456359 | T18: 0.013414865 | U18: =S18-T18 -> 0.0040414945
A19: https://en.wikipedia.org/wiki/Boston_University | C19: Boston University | D19: Boston University | E19: Terriers | F19: Boston | G19: MA | H19: Private | I19: Non-football | J19: Patriot League | K19: 0 | L19: 0 | M19: 0 | N19: 0 | O19: American Football | P19: 10 | Q19: =P19*N19 -> 0 | R19: {=IF(O19="American Football", XLOOKUP(C19, drafts_football!A:A, drafts_football!B:B, 0), "")} -> 0 | S19: =IF(Q19 = 0, 0, R19/Q19) -> 0 | T19: 0.013414865 | U19: =S19-T19 -> -0.013414865
A20: https://en.wikipedia.org/wiki/Bowling_Green_State_University | B20: https://www.sports-reference.com/cfb/schools/bowling-green-state/ | C20: Bowling Green State University | D20: Bowling Green | E20: Falcons | F20: Bowling Green | G20: OH | H20: Public | I20: FBS | J20: Mid-American Conference | K20: 107 | L20: 109 | M20: 107 | N20: 107.7 | O20: American Football | P20: 10 | Q20: =P20*N20 -> 1077 | R20: {=IF(O20="American Football", XLOOKUP(C20, drafts_football!A:A, drafts_football!B:B, 0), "")} -> 3 | S20: =IF(Q20 = 0, 0, R20/Q20) -> 0.0027855153 | T20: 0.013414865 | U20: =S20-T20 -> -0.010629349
A21: https://en.wikipedia.org/wiki/Bradley_University | C21: Bradley University | D21: Bradley | E21: Braves | F21: Peoria | G21: IL | H21: Private | I21: Non-football | J21: Missouri Valley Conference | K21: 0 | L21: 0 | M21: 0 | N21: 0 | O21: American Football | P21: 10 | Q21: =P21*N21 -> 0 | R21: {=IF(O21="American Football", XLOOKUP(C21, drafts_football!A:A, drafts_football!B:B, 0), "")} -> 0 | S21: =IF(Q21 = 0, 0, R21/Q21) -> 0 | T21: 0.013414865 | U21: =S21-T21 -> -0.013414865
A22: https://en.wikipedia.org/wiki/Brigham_Young_University | B22: https://www.sports-reference.com/cfb/schools/brigham-young/ | C22: Brigham Young University | D22: BYU | E22: Cougars | F22: Provo | G22: UT | H22: Private | I22: FBS | J22: Big 12 Conference | K22: 115 | L22: 121 | M22: 119 | N22: 118.3 | O22: American Football | P22: 10 | Q22: =P22*N22 -> 1183 | R22: {=IF(O22="American Football", XLOOKUP(C22, drafts_football!A:A, drafts_football!B:B, 0), "")} -> 14 | S22: =IF(Q22 = 0, 0, R22/Q22) -> 0.01183432 | T22: 0.013414865 | U22: =S22-T22 -> -0.001580545
A23: https://en.wikipedia.org/wiki/Brown_University | C23: Brown University | D23: Brown | E23: Bears | F23: Providence | G23: RI | H23: Private | I23: FCS | J23: Ivy League | N23: 0 | O23: American Football | P23: 10 | Q23: =P23*N23 -> 0 | R23: {=IF(O23="American Football", XLOOKUP(C23, drafts_football!A:A, drafts_football!B:B, 0), "")} -> 0 | S23: =IF(Q23 = 0, 0, R23/Q23) -> 0 | T23: 0.013414865 | U23: =S23-T23 -> -0.013414865
A24: https://en.wikipedia.org/wiki/Bryant_University | C24: Bryant University | D24: Bryant | E24: Bulldogs | F24: Smithfield | G24: RI | H24: Private | I24: FCS | J24: America East Conference | N24: 0 | O24: American Football | P24: 10 | Q24: =P24*N24 -> 0 | R24: {=IF(O24="American Football", XLOOKUP(C24, drafts_football!A:A, drafts_football!B:B, 0), "")} -> 0 | S24: =IF(Q24 = 0, 0, R24/Q24) -> 0 | T24: 0.013414865 | U24: =S24-T24 -> -0.013414865
A25: https://en.wikipedia.org/wiki/Bucknell_University | C25: Bucknell University | D25: Bucknell | E25: Bison | F25: Lewisburg | G25: PA | H25: Private | I25: FCS | J25: Patriot League | N25: 0 | O25: American Football | P25: 10 | Q25: =P25*N25 -> 0 | R25: {=IF(O25="American Football", XLOOKUP(C25, drafts_football!A:A, drafts_football!B:B, 0), "")} -> 1 | S25: =IF(Q25 = 0, 0, R25/Q25) -> 0 | T25: 0.013414865 | U25: =S25-T25 -> -0.013414865
A26: https://en.wikipedia.org/wiki/Butler_University | C26: Butler University | D26: Butler | E26: Bulldogs | F26: Indianapolis | G26: IN | H26: Private | I26: FCS | J26: Big East Conference | N26: 0 | O26: American Football | P26: 10 | Q26: =P26*N26 -> 0 | R26: {=IF(O26="American Football", XLOOKUP(C26, drafts_football!A:A, drafts_football!B:B, 0), "")} -> 0 | S26: =IF(Q26 = 0, 0, R26/Q26) -> 0 | T26: 0.013414865 | U26: =S26-T26 -> -0.013414865
A27: https://en.wikipedia.org/wiki/California_Baptist_University | C27: California Baptist University | D27: Cal Baptist | E27: Lancers | F27: Riverside | G27: CA | H27: Private | I27: Non-football | J27: Western Athletic Conference | K27: 0 | L27: 0 | M27: 0 | N27: 0 | O27: American Football | P27: 10 | Q27: =P27*N27 -> 0 | R27: {=IF(O27="American Football", XLOOKUP(C27, drafts_football!A:A, drafts_football!B:B, 0), "")} -> 0 | S27: =IF(Q27 = 0, 0, R27/Q27) -> 0 | T27: 0.013414865 | U27: =S27-T27 -> -0.013414865
A28: https://en.wikipedia.org/wiki/California_Polytechnic_State_University,_San_Luis_Obispo | C28: California Polytechnic State University | D28: Cal Poly | E28: Mustangs | F28: San Luis Obispo | G28: CA | H28: Public | I28: FCS | J28: Big West Conference | N28: 0 | O28: American Football | P28: 10 | Q28: =P28*N28 -> 0 | R28: {=IF(O28="American Football", XLOOKUP(C28, drafts_football!A:A, drafts_football!B:B, 0), "")} -> 0 | S28: =IF(Q28 = 0, 0, R28/Q28) -> 0 | T28: 0.013414865 | U28: =S28-T28 -> -0.013414865
A29: https://en.wikipedia.org/wiki/California_State_University,_Bakersfield | C29: California State University, Bakersfield | D29: Bakersfield | E29: Roadrunners | F29: Bakersfield | G29: CA | H29: Public | I29: Non-football | J29: Big West Conference | K29: 0 | L29: 0 | M29: 0 | N29: 0 | O29: American Football | P29: 10 | Q29: =P29*N29 -> 0 | R29: {=IF(O29="American Football", XLOOKUP(C29, drafts_football!A:A, drafts_football!B:B, 0), "")} -> 0 | S29: =IF(Q29 = 0, 0, R29/Q29) -> 0 | T29: 0.013414865 | U29: =S29-T29 -> -0.013414865
A30: https://en.wikipedia.org/wiki/California_State_University,_Fresno | B30: https://www.sports-reference.com/cfb/schools/fresno-state/ | C30: California State University, Fresno | D30: Fresno State | E30: Bulldogs | F30: Fresno | G30: CA | H30: Public | I30: FBS | J30: Mountain West Conference | K30: 113 | L30: 115 | M30: 112 | N30: 113.3 | O30: American Football | P30: 10 | Q30: =P30*N30 -> 1133 | R30: {=IF(O30="American Football", XLOOKUP(C30, drafts_football!A:A, drafts_football!B:B, 0), "")} -> 5 | S30: =IF(Q30 = 0, 0, R30/Q30) -> 0.0044130627 | T30: 0.013414865 | U30: =S30-T30 -> -0.0090018019
A31: https://en.wikipedia.org/wiki/California_State_University,_Fullerton | C31: California State University, Fullerton | D31: Cal State Fullerton | E31: Titans | F31: Fullerton | G31: CA | H31: Public | I31: Non-football | J31: Big West Conference | K31: 0 | L31: 0 | M31: 0 | N31: 0 | O31: American Football | P31: 10 | Q31: =P31*N31 -> 0 | R31: {=IF(O31="American Football", XLOOKUP(C31, drafts_football!A:A, drafts_football!B:B, 0), "")} -> 0 | S31: =IF(Q31 = 0, 0, R31/Q31) -> 0 | T31: 0.013414865 | U31: =S31-T31 -> -0.013414865
A32: https://en.wikipedia.org/wiki/California_State_University,_Long_Beach | C32: California State University, Long Beach | D32: Long Beach State | E32: Beach | F32: Long Beach | G32: CA | H32: Public | I32: Non-football | J32: Big West Conference | K32: 0 | L32: 0 | M32: 0 | N32: 0 | O32: American Football | P32: 10 | Q32: =P32*N32 -> 0 | R32: {=IF(O32="American Football", XLOOKUP(C32, drafts_football!A:A, drafts_football!B:B, 0), "")} -> 0 | S32: =IF(Q32 = 0, 0, R32/Q32) -> 0 | T32: 0.013414865 | U32: =S32-T32 -> -0.013414865
A33: https://en.wikipedia.org/wiki/California_State_University,_Northridge | C33: California State University, Northridge | D33: Cal State Northridge / CSUN | E33: Matadors | F33: Northridge | G33: CA | H33: Public | I33: Non-football | J33: Big West Conference | K33: 0 | L33: 0 | M33: 0 | N33: 0 | O33: American Football | P33: 10 | Q33: =P33*N33 -> 0 | R33: {=IF(O33="American Football", XLOOKUP(C33, drafts_football!A:A, drafts_football!B:B, 0), "")} -> 0 | S33: =IF(Q33 = 0, 0, R33/Q33) -> 0 | T33: 0.013414865 | U33: =S33-T33 -> -0.013414865
A34: https://en.wikipedia.org/wiki/California_State_University,_Sacramento | C34: California State University, Sacramento | D34: Sacramento State | E34: Hornets | F34: Sacramento | G34: CA | H34: Public | I34: FCS | J34: Big Sky Conference | N34: 0 | O34: American Football | P34: 10 | Q34: =P34*N34 -> 0 | R34: {=IF(O34="American Football", XLOOKUP(C34, drafts_football!A:A, drafts_football!B:B, 0), "")} -> 2 | S34: =IF(Q34 = 0, 0, R34/Q34) -> 0 | T34: 0.013414865 | U34: =S34-T34 -> -0.013414865
A35: https://en.wikipedia.org/wiki/Campbell_University | C35: Campbell University | D35: Campbell | E35: Fighting Camels | F35: Buies Creek | G35: NC | H35: Private | I35: FCS | J35: Coastal Athletic Association | N35: 0 | O35: American Football | P35: 10 | Q35: =P35*N35 -> 0 | R35: {=IF(O35="American Football", XLOOKUP(C35, drafts_football!A:A, drafts_football!B:B, 0), "")} -> 0 | S35: =IF(Q35 = 0, 0, R35/Q35) -> 0 | T35: 0.013414865 | U35: =S35-T35 -> -0.013414865
A36: https://en.wikipedia.org/wiki/Canisius_University | C36: Canisius University | D36: Canisius | E36: Golden Griffins | F36: Buffalo | G36: NY | H36: Private | I36: Non-football | J36: Metro Atlantic Athletic Conference | K36: 0 | L36: 0 | M36: 0 | N36: 0 | O36: American Football | P36: 10 | Q36: =P36*N36 -> 0 | R36: {=IF(O36="American Football", XLOOKUP(C36, drafts_football!A:A, drafts_football!B:B, 0), "")} -> 0 | S36: =IF(Q36 = 0, 0, R36/Q36) -> 0 | T36: 0.013414865 | U36: =S36-T36 -> -0.013414865
A37: https://en.wikipedia.org/wiki/Central_Connecticut_State_University | C37: Central Connecticut State University | D37: Central Connecticut | E37: Blue Devils | F37: New Britain | G37: CT | H37: Public | I37: FCS | J37: NEC | N37: 0 | O37: American Football | P37: 10 | Q37: =P37*N37 -> 0 | R37: {=IF(O37="American Football", XLOOKUP(C37, drafts_football!A:A, drafts_football!B:B, 0), "")} -> 0 | S37: =IF(Q37 = 0, 0, R37/Q37) -> 0 | T37: 0.013414865 | U37: =S37-T37 -> -0.013414865
A38: https://en.wikipedia.org/wiki/Central_Michigan_University | B38: https://www.sports-reference.com/cfb/schools/central-michigan/ | C38: Central Michigan University | D38: Central Michigan | E38: Chippewas | F38: Mount Pleasant | G38: MI | H38: Public | I38: FBS | J38: Mid-American Conference | K38: 104 | L38: 120 | M38: 115 | N38: 113 | O38: American Football | P38: 10 | Q38: =P38*N38 -> 1130 | R38: {=IF(O38="American Football", XLOOKUP(C38, drafts_football!A:A, drafts_football!B:B, 0), "")} -> 8 | S38: =IF(Q38 = 0, 0, R38/Q38) -> 0.007079646 | T38: 0.013414865 | U38: =S38-T38 -> -0.0063352185
A39: https://en.wikipedia.org/wiki/Charleston_Southern_University | C39: Charleston Southern University | D39: Charleston Southern | E39: Buccaneers | F39: North Charleston | G39: SC | H39: Private | I39: FCS | J39: Big South Conference | N39: 0 | O39: American Football | P39: 10 | Q39: =P39*N39 -> 0 | R39: {=IF(O39="American Football", XLOOKUP(C39, drafts_football!A:A, drafts_football!B:B, 0), "")} -> 0 | S39: =IF(Q39 = 0, 0, R39/Q39) -> 0 | T39: 0.013414865 | U39: =S39-T39 -> -0.013414865
A40: https://en.wikipedia.org/wiki/Chicago_State_University | C40: Chicago State University | D40: Chicago State | E40: Cougars | F40: Chicago | G40: IL | H40: Public | I40: Non-football | J40: NEC | K40: 0 | L40: 0 | M40: 0 | N40: 0 | O40: American Football | P40: 10 | Q40: =P40*N40 -> 0 | R40: {=IF(O40="American Football", XLOOKUP(C40, drafts_football!A:A, drafts_football!B:B, 0), "")} -> 0 | S40: =IF(Q40 = 0, 0, R40/Q40) -> 0 | T40: 0.013414865 | U40: =S40-T40 -> -0.013414865
...

Sheet Top_Football
A1: School name | B1: State | C1: Conference | D1: Estimated Athlete pool | E1: Pro Players Count | F1: Draft Probability | G1: National Average | H1: Vs_National_Average
A2: Ohio State | B2: OH | C2: Big Ten Conference | D2: 1213 | E2: 84 | F2: 0.069249794 | G2: 0.013414865 | H2: 0.055834929
A3: Alabama | B3: AL | C3: Southeastern Conference | D3: 1327 | E3: 90 | F3: 0.067822155 | G3: 0.013414865 | H3: 0.054407291
A4: Georgia | B4: GA | C4: Southeastern Conference | D4: 1293 | E4: 80 | F4: 0.061871616 | G4: 0.013414865 | H4: 0.048456752
A5: Michigan | B5: MI | C5: Big Ten Conference | D5: 1333 | E5: 73 | F5: 0.054763691 | G5: 0.013414865 | H5: 0.041348826
A6: Florida | B6: FL | C6: Southeastern Conference | D6: 1233 | E6: 57 | F6: 0.04622871 | G6: 0.013414865 | H6: 0.032813846
A7: Notre Dame | B7: IN | C7: Atlantic Coast Conference | D7: 1170 | E7: 52 | F7: 0.044444444 | G7: 0.013414865 | H7: 0.03102958
A8: Penn State | B8: PA | C8: Big Ten Conference | D8: 1280 | E8: 56 | F8: 0.04375 | G8: 0.013414865 | H8: 0.030335135
A9: Clemson | B9: SC | C9: Atlantic Coast Conference | D9: 1327 | E9: 52 | F9: 0.039186134 | G9: 0.013414865 | H9: 0.02577127
A10: Miami (Florida) | B10: FL | C10: Atlantic Coast Conference | D10: 1150 | E10: 45 | F10: 0.039130435 | G10: 0.013414865 | H10: 0.02571557
A11: Texas | B11: TX | C11: Southeastern Conference | D11: 1163 | E11: 45 | F11: 0.038693035 | G11: 0.013414865 | H11: 0.025278171
A12: Oklahoma | B12: OK | C12: Southeastern Conference | D12: 1210 | E12: 46 | F12: 0.038016529 | G12: 0.013414865 | H12: 0.024601664
A13: Washington | B13: WA | C13: Big Ten Conference | D13: 1113 | E13: 41 | F13: 0.036837376 | G13: 0.013414865 | H13: 0.023422512
... A129: Texas State | B129: TX | C129: Sun Belt Conference | D129: 1170 | E129: 0 | F129: 0 | G129: 0.013414865 | H129: -0.013414865

Sheet MLB-athlete-per-school-count
A1: Drafted Out of | B1: City | C1: State | D1: Pro Players Count | E1: Num of Seasons | F1: Roster count 2026 | G1: Roster count 2025 | H1: Roster count 2024 | I1: Avg Roster Count Last 3 years | J1: Estimated Athlete Pool | K1: Draft Probability | L1: National Average | M1: Vs_National_Average
A2: University of Arkansas | B2: Fayetteville | C2: AR | D2: 76 | E2: 10 | F2: 34 | G2: 40 | H2: 40 | I2: 35 | J2: =I2*E2 -> 350 | K2: =D2/J2 -> 0.21714286 | L2: 0.026573227 | M2: =K2-L2 -> 0.19056963
A3: Vanderbilt University | B3: Nashville | C3: TN | D3: 72 | E3: 10 | F3: 34 | G3: 40 | H3: 40 | I3: 35 | J3: =I3*E3 -> 350 | K3: =D3/J3 -> 0.20571429 | L3: 0.026573227 | M3: =K3-L3 -> 0.17914106
A4: Louisiana State University | B4: Baton Rouge | C4: LA | D4: 68 | E4: 10 | F4: 34 | G4: 40 | H4: 40 | I4: 35 | J4: =I4*E4 -> 350 | K4: =D4/J4 -> 0.19428571 | L4: 0.026573227 | M4: =K4-L4 -> 0.16771249
A5: Mississippi State University | B5: Mississippi State | C5: MS | D5: 67 | E5: 10 | F5: 34 | G5: 40 | H5: 40 | I5: 35 | J5: =I5*E5 -> 350 | K5: =D5/J5 -> 0.19142857 | L5: 0.026573227 | M5: =K5-L5 -> 0.16485534
A6: Oklahoma State University | B6: Stillwater | C6: OK | D6: 62 | E6: 10 | F6: 34 | G6: 40 | H6: 40 | I6: 35 | J6: =I6*E6 -> 350 | K6: =D6/J6 -> 0.17714286 | L6: 0.026573227 | M6: =K6-L6 -> 0.15056963
A7: University of Tennessee | B7: Knoxville | C7: TN | D7: 62 | E7: 10 | F7: 34 | G7: 40 | H7: 40 | I7: 35 | J7: =I7*E7 -> 350 | K7: =D7/J7 -> 0.17714286 | L7: 0.026573227 | M7: =K7-L7 -> 0.15056963
A8: Texas A&M University | B8: College Station | C8: TX | D8: 60 | E8: 10 | F8: 34 | G8: 40 | H8: 40 | I8: 35 | J8: =I8*E8 -> 350 | K8: =D8/J8 -> 0.17142857 | L8: 0.026573227 | M8: =K8-L8 -> 0.14485534
A9: Texas Tech University | B9: Lubbock | C9: TX | D9: 59 | E9: 10 | F9: 34 | G9: 40 | H9: 40 | I9: 35 | J9: =I9*E9 -> 350 | K9: =D9/J9 -> 0.16857143 | L9: 0.026573227 | M9: =K9-L9 -> 0.1419982
A10: University of Mississippi | B10: Oxford | C10: MS | D10: 59 | E10: 10 | F10: 34 | G10: 40 | H10: 40 | I10: 35 | J10: =I10*E10 -> 350 | K10: =D10/J10 -> 0.16857143 | L10: 0.026573227 | M10: =K10-L10 -> 0.1419982
A11: University of Louisville | B11: Louisville | C11: KY | D11: 59 | E11: 10 | F11: 34 | G11: 40 | H11: 40 | I11: 35 | J11: =I11*E11 -> 350 | K11: =D11/J11 -> 0.16857143 | L11: 0.026573227 | M11: =K11-L11 -> 0.1419982
A12: University of Oklahoma | B12: Norman | C12: OK | D12: 57 | E12: 10 | F12: 34 | G12: 40 | H12: 40 | I12: 35 | J12: =I12*E12 -> 350 | K12: =D12/J12 -> 0.16285714 | L12: 0.026573227 | M12: =K12-L12 -> 0.13628392
A13: University of Florida | B13: Gainesville | C13: FL | D13: 56 | E13: 10 | F13: 34 | G13: 40 | H13: 40 | I13: 35 | J13: =I13*E13 -> 350 | K13: =D13/J13 -> 0.16 | L13: 0.026573227 | M13: =K13-L13 -> 0.13342677
... A553: Northern Oklahoma College-Tonkawa | B553: Tonkawa | C553: OK | D553: 1 | E553: 10 | F553: 34 | G553: 40 | H553: 40 | I553: 35 | J553: =I553*E553 -> 350 | K553: =D553/J553 -> 0.0028571429 | L553: 0.026573227 | M553: =K553-L553 -> -0.023716084
K554: =AVERAGE(K2:K553) -> 0.028850932

Sheet MLB-athlete-all-data-drafts
A1: Year | B1: Rnd | C1: OvPck | D1: RdPck | E1: Tm | F1: Signed | G1: Bonus | H1: Name | I1: Pos | J1: WAR | K1: G | L1: AB | M1: HR | N1: BA | O1: OPS | P1: G.1 | Q1: W | R1: L | S1: ERA | T1: WHIP | U1: SV | V1: Type | W1: Drafted Out of
A2: 2016 | B2: 1 | C2: 2 | D2: 2 | E2: Reds | F2: Y | G2: $6,200,000 | H2: Nick Senzel (minors) | I2: 3B | J2: -3.1 | K2: 451 | L2: 1466 | M2: 40 | N2: 0.232 | O2: 0.662 | V2: 4Yr | W2: University of Tennessee (Knoxville, TN)
A3: 2016 | B3: 1 | C3: 5 | D3: 5 | E3: Brewers | F3: Y | G3: $4,800,000 | H3: Corey Ray (minors) | I3: OF | J3: 0 | K3: 1 | L3: 2 | M3: 0 | N3: 0 | O3: 0.333 | V3: 4Yr | W3: University of Louisville (Louisville, KY)
A4: 2016 | B4: 1 | C4: 6 | D4: 6 | E4: Athletics | F4: Y | G4: $4,125,000 | H4: A.J. Puk (minors) | I4: LHP | J4: 3.4 | K4: 3 | L4: 0 | M4: 0 | P4: 212 | Q4: 17 | R4: 20 | S4: 3.53 | T4: 1.19 | U4: 26 | V4: 4Yr | W4: University of Florida (Gainesville, FL)
A5: 2016 | B5: 1 | C5: 8 | D5: 8 | E5: Padres | F5: Y | G5: $4,145,900 | H5: Cal Quantrill (minors) | I5: RHP | J5: 7.8 | K5: 24 | L5: 27 | M5: 0 | N5: 0.111 | O5: 0.254 | P5: 187 | Q5: 47 | R5: 46 | S5: 4.35 | T5: 1.33 | U5: 1 | V5: 4Yr | W5: Stanford University (Palo Alto, CA)
A6: 2016 | B6: 1 | C6: 10 | D6: 10 | E6: White Sox | F6: Y | G6: $3,380,600 | H6: Zack Collins (minors) | I6: C | J6: -1.1 | K6: 152 | L6: 398 | M6: 11 | N6: 0.188 | O6: 0.629 | V6: 4Yr | W6: University of Miami (Coral Gables, FL)
A7: 2016 | B7: 1 | C7: 11 | D7: 11 | E7: Mariners | F7: Y | G7: $3,286,700 | H7: Kyle Lewis (minors) | I7: OF | J7: 1.8 | K7: 146 | L7: 514 | M7: 26 | N7: 0.235 | O7: 0.732 | V7: 4Yr | W7: Mercer University (Macon, GA)
A8: 2016 | B8: 1 | C8: 16 | D8: 16 | E8: Angels | F8: Y | G8: $2,150,000 | H8: Matt Thaiss (minors) | I8: C | J8: 1.9 | K8: 305 | L8: 819 | M8: 23 | N8: 0.21 | O8: 0.652 | V8: 4Yr | W8: University of Virginia (Charlottesville, VA)
A9: 2016 | B9: 1 | C9: 19 | D9: 19 | E9: Mets | F9: Y | G9: $2,378,800 | H9: Justin Dunn (minors) | I9: RHP | J9: 1.5 | K9: 3 | L9: 4 | M9: 0 | N9: 0.25 | O9: 0.75 | P9: 32 | Q9: 6 | R9: 7 | S9: 4.44 | T9: 1.41 | U9: 0 | V9: 4Yr | W9: Boston College (Chestnut Hill, MA)
A10: 2016 | B10: 1 | C10: 21 | D10: 21 | E10: Blue Jays | F10: Y | G10: $2,175,000 | H10: T.J. Zeuch (minors) | I10: RHP | J10: -0.6 | K10: 1 | L10: 1 | M10: 0 | N10: 0 | O10: 0 | P10: 16 | Q10: 2 | R10: 7 | S10: 6.49 | T10: 1.79 | U10: 0 | V10: 4Yr | W10: University of Pittsburgh (Pittsburgh, PA)
A11: 2016 | B11: 1 | C11: 22 | D11: 22 | E11: Pirates | F11: Y | G11: $2,253,700 | H11: Will Craig (minors) | I11: 3B | J11: -0.7 | K11: 20 | L11: 64 | M11: 1 | N11: 0.203 | O11: 0.542 | V11: 4Yr | W11: Wake Forest University (Winston-Salem, NC)
A12: 2016 | B12: 1 | C12: 25 | D12: 25 | E12: Padres | F12: Y | G12: $2,000,000 | H12: Eric Lauer (minors) | I12: LHP | J12: 5.8 | K12: 76 | L12: 96 | M12: 1 | N12: 0.104 | O12: 0.321 | P12: 150 | Q12: 46 | R12: 40 | S12: 4.14 | T12: 1.33 | U12: 0 | V12: 4Yr | W12: Kent State University (Kent, OH)
A13: 2016 | B13: 1 | C13: 26 | D13: 26 | E13: White Sox | F13: Y | G13: $2,128,500 | H13: Zack Burdi (minors) | I13: RHP | J13: -0.8 | K13: 0 | L13: 0 | M13: 0 | P13: 18 | Q13: 0 | R13: 1 | S13: 8.44 | T13: 1.88 | U13: 0 | V13: 4Yr | W13: University of Louisville (Louisville, KY)
A14: 2016 | B14: 1 | C14: 27 | D14: 27 | E14: Orioles | F14: Y | G14: $2,097,200 | H14: Cody Sedlock (minors) | I14: RHP | J14: -0.1 | K14: 0 | L14: 0 | M14: 0 | P14: 1 | Q14: 0 | R14: 0 | S14: 15 | T14: 2.33 | U14: 0 | V14: 4Yr | W14: University of Illinois at Urbana-Champaign (Champaign, IL)
A15: 2016 | B15: 1 | C15: 29 | D15: 29 | E15: Nationals | F15: Y | G15: $2,000,000 | H15: Dane Dunning (minors) | I15: RHP | J15: 3.5 | K15: 2 | L15: 3 | M15: 0 | N15: 0.333 | O15: 0.667 | P15: 136 | Q15: 28 | R15: 32 | S15: 4.44 | T15: 1.37 | U15: 2 | V15: 4Yr | W15: University of Florida (Gainesville, FL)
A16: 2016 | B16: 1 | C16: 31 | D16: 31 | E16: Mets | F16: Y | G16: $1,100,000 | H16: Anthony Kay (minors) | I16: LHP | J16: 0.1 | K16: 4 | L16: 0 | M16: 0 | P16: 46 | Q16: 4 | R16: 2 | S16: 5.44 | T16: 1.58 | U16: 0 | V16: 4Yr | W16: University of Connecticut (Storrs, CT)
A17: 2016 | B17: 1 | C17: 32 | D17: 32 | E17: Dodgers | F17: Y | G17: $1,772,500 | H17: Will Smith (minors) | I17: C | J17: 23 | K17: 732 | L17: 2542 | M17: 130 | N17: 0.263 | O17: 0.832 | V17: 4Yr | W17: University of Louisville (Louisville, KY)
A18: 2016 | B18: 1 | C18: 34 | D18: 34 | E18: Cardinals | F18: Y | G18: $2,000,000 | H18: Dakota Hudson (minors) | I18: RHP | J18: 3.5 | K18: 56 | L18: 55 | M18: 0 | N18: 0.091 | O18: 0.214 | P18: 132 | Q18: 40 | R18: 32 | S18: 4.21 | T18: 1.43 | U18: 1 | V18: 4Yr | W18: Mississippi State University (Mississippi State, MS)
A19: 2016 | B19: 1 | C19: 36 | D19: 36 | E19: Dodgers | F19: Y | G19: $1,847,500 | H19: Jordan Sheffield (minors) | I19: RHP | J19: 0.7 | K19: 30 | L19: 0 | M19: 0 | P19: 32 | Q19: 0 | R19: 0 | S19: 3.16 | T19: 1.15 | U19: 0 | V19: 4Yr | W19: Vanderbilt University (Nashville, TN)
A20: 2016 | B20: 1 | C20: 37 | D20: 37 | E20: Athletics | F20: Y | G20: $1,600,000 | H20: Daulton Jefferies (minors) | I20: RHP | J20: -1 | K20: 0 | L20: 0 | M20: 0 | P20: 20 | Q20: 2 | R20: 10 | S20: 6.59 | T20: 1.46 | U20: 0 | V20: 4Yr | W20: University of California, Berkeley (Berkeley, CA)
A21: 2016 | B21: 1 | C21: 38 | D21: 38 | E21: Rockies | F21: Y | G21: $1,701,600 | H21: Robert Tyler (minors) | I21: RHP | V21: 4Yr | W21: University of Georgia (Athens, GA)
A22: 2016 | B22: 1 | C22: 39 | D22: 39 | E22: Diamondbacks | F22: Y | G22: $1,500,000 | H22: Anfernee Grier (minors) | I22: OF | V22: 4Yr | W22: Auburn University (Auburn, AL)
A23: 2016 | B23: 2 | C23: 43 | D23: 2 | E23: Reds | F23: Y | G23: $2,000,000 | H23: Chris Okey (minors) | I23: C | J23: -0.3 | K23: 9 | L23: 14 | M23: 0 | N23: 0.143 | O23: 0.343 | V23: 4Yr | W23: Clemson University (Clemson, SC)
A24: 2016 | B24: 2 | C24: 45 | D24: 4 | E24: Rockies | F24: Y | G24: $1,600,000 | H24: Ben Bowden (minors) | I24: LHP | J24: -0.6 | K24: 36 | L24: 0 | M24: 0 | P24: 50 | Q24: 3 | R24: 2 | S24: 6.02 | T24: 1.71 | U24: 0 | V24: 4Yr | W24: Vanderbilt University (Nashville, TN)
A25: 2016 | B25: 2 | C25: 46 | D25: 5 | E25: Brewers | F25: Y | G25: $1,150,000 | H25: Lucas Erceg (minors) | I25: 3B | J25: 2.8 | K25: 2 | L25: 0 | M25: 0 | P25: 177 | Q25: 14 | R25: 14 | S25: 3.55 | T25: 1.26 | U25: 19 | V25: 4Yr | W25: Menlo College (Atherton, CA)
A26: 2016 | B26: 2 | C26: 47 | D26: 6 | E26: Athletics | F26: Y | G26: $1,500,000 | H26: Logan Shore (minors) | I26: RHP | V26: 4Yr | W26: University of Florida (Gainesville, FL)
A27: 2016 | B27: 2 | C27: 48 | D27: 7 | E27: Padres | F27: Y | G27: $1,075,000 | H27: Michael Reed (minors) | I27: OF | V27: 4Yr | W27: University of Florida (Gainesville, FL)
A28: 2016 | B28: 2 | C28: 49 | D28: 8 | E28: White Sox | F28: Y | G28: $1,200,000 | H28: Alec Hansen (minors) | I28: RHP | V28: 4Yr | W28: University of Oklahoma (Norman, OK)
A29: 2016 | B29: 2 | C29: 51 | D29: 10 | E29: Red Sox | F29: Y | G29: $1,100,000 | H29: C.J. Chatham (minors) | I29: SS | V29: 4Yr | W29: Florida Atlantic University (Boca Raton, FL)
A30: 2016 | B30: 2 | C30: 53 | D30: 12 | E30: Rays | F30: Y | G30: $997,500 | H30: Ryan Boldt (minors) | I30: OF | V30: 4Yr | W30: University of Nebraska-Lincoln (Lincoln, NE)
A31: 2016 | B31: 2 | C31: 54 | D31: 13 | E31: Orioles | F31: Y | G31: $1,177,200 | H31: Keegan Akin (minors) | I31: LHP | J31: 1.9 | K31: 4 | L31: 2 | M31: 0 | N31: 0 | O31: 0 | P31: 231 | Q31: 16 | R31: 22 | S31: 4.48 | T31: 1.3 | U31: 11 | V31: 4Yr | W31: Western Michigan University (Kalamazoo, MI)
A32: 2016 | B32: 2 | C32: 57 | D32: 16 | E32: Blue Jays | F32: Y | G32: $975,000 | H32: J.B. Woodman (minors) | I32: OF | V32: 4Yr | W32: University of Mississippi (Oxford, MS)
A33: 2016 | B33: 2 | C33: 58 | D33: 17 | E33: Nationals | F33: Y | G33: $900,000 | H33: Sheldon Neuse (minors) | I33: 3B | J33: -0.8 | K33: 147 | L33: 392 | M33: 7 | N33: 0.212 | O33: 0.558 | P33: 3 | Q33: 0 | R33: 0 | S33: 0 | T33: 0.27 | U33: 0 | V33: 4Yr | W33: University of Oklahoma (Norman, OK)
A34: 2016 | B34: 2 | C34: 59 | D34: 18 | E34: Giants | F34: Y | G34: $1,350,000 | H34: Bryan Reynolds (minors) | I34: OF | J34: 21.3 | K34: 959 | L34: 3603 | M34: 140 | N34: 0.271 | O34: 0.804 | V34: 4Yr | W34: Vanderbilt University (Nashville, TN)
A35: 2016 | B35: 2 | C35: 61 | D35: 20 | E35: Astros | F35: Y | G35: $1,056,800 | H35: Ronnie Dawson (minors) | I35: OF | J35: -0.2 | K35: 4 | L35: 8 | M35: 0 | N35: 0.125 | O35: 0.347 | V35: 4Yr | W35: The Ohio State University (Columbus, OH)
A36: 2016 | B36: 2 | C36: 62 | D36: 21 | E36: Yankees | F36: Y | G36: $950,000 | H36: Nick Solak (minors) | I36: 2B | J36: 0 | K36: 259 | L36: 876 | M36: 21 | N36: 0.25 | O36: 0.694 | V36: 4Yr | W36: University of Louisville (Louisville, KY)
A37: 2016 | B37: 2 | C37: 64 | D37: 23 | E37: Mets | F37: Y | G37: $909,200 | H37: Pete Alonso (minors) | I37: 1B | J37: 23.3 | K37: 1019 | L37: 3806 | M37: 265 | N37: 0.252 | O37: 0.853 | V37: 4Yr | W37: University of Florida (Gainesville, FL)
A38: 2016 | B38: 2 | C38: 65 | D38: 24 | E38: Dodgers | F38: Y | G38: $588,300 | H38: Mitch White (minors) | I38: RHP | J38: -2 | K38: 21 | L38: 15 | M38: 0 | N38: 0 | O38: 0.063 | P38: 71 | Q38: 4 | R38: 12 | S38: 5.25 | T38: 1.42 | U38: 0 | V38: 4Yr | W38: Santa Clara University (Santa Clara, CA)
A39: 2016 | B39: 2 | C39: 67 | D39: 26 | E39: Royals | F39: Y | G39: $1,200,000 | H39: A.J. Puckett (minors) | I39: RHP | V39: 4Yr | W39: Pepperdine University (Malibu, CA)
